Workbook

Sheet Ведомость материалов
A1: Ведомость материалов · Квартира 56 м² · без цен
A2: Количество = объём × норма × (1 + запас), к покупке — с округлением вверх до целой упаковки. Синие ячейки можно менять. Колонки цен заполняет поставщик.
A4: № | B4: Материал | C4: Ед. | D4: Объём | E4: Основание | F4: Норма на ед. | G4: Запас | H4: Нужно | I4: Фасовка | J4: Ед. фасовки | K4: К покупке | L4: Примечание | M4: Цена за ед. фасовки | N4: Сумма
B5: 1. Перегородки из ГКЛ (ПГ-1, ПГ-2) | L5: каркас ПС-75, ГКЛ 12,5 мм с двух сторон, минвата 50 мм
A6: 1 | B6: ГКЛ 12,5 мм, лист 1200×3000 | C6: м² | D6: =Объёмы!C23 -> 27.96 | E6: Перегородки ГКЛ (ПГ-1, ПГ-2) за вычетом проёмов, м² | F6: 2 | G6: 0.1 | H6: =D6*F6*(1+G6) -> 61.512 | I6: 3.6 | J6: лист | K6: =ROUNDUP(H6/I6,0) -> 18 | L6: 2 стороны перегородки | N6: =IF(M6="","",K6*M6)
A7: 2 | B7: Профиль направляющий ПН-75, 3 м | C7: м | D7: =Объёмы!C24 -> 10.6 | E7: Длина перегородок ГКЛ, м | F7: 2 | G7: 0.15 | H7: =D7*F7*(1+G7) -> 24.38 | I7: 3 | J7: шт | K7: =ROUNDUP(H7/I7,0) -> 9 | L7: пол + потолок, перемычки над проёмами | N7: =IF(M7="","",K7*M7)
A8: 3 | B8: Профиль стоечный ПС-75, 3 м | C8: шт | D8: =Объёмы!C25 -> 25 | E8: Стойки ПС-75: шаг 600 + 4 у проёмов, шт | F8: 1 | G8: 0.1 | H8: =D8*F8*(1+G8) -> 27.5 | I8: 1 | J8: шт | K8: =ROUNDUP(H8/I8,0) -> 28 | L8: шаг 600 + 2 у каждого проёма | N8: =IF(M8="","",K8*M8)
A9: 4 | B9: Брус сухой 50×50 для усиления проёмов, 3 м | C9: шт | D9: 2 | E9: по проекту | F9: 3 | G9: 0 | H9: =D9*F9*(1+G9) -> 6 | I9: 1 | J9: шт | K9: =ROUNDUP(H9/I9,0) -> 6 | L9: по 3 на проём Д-2 и П-1 | N9: =IF(M9="","",K9*M9)
A10: 5 | B10: Минвата акустическая 50 мм | C10: м² | D10: =Объёмы!C23 -> 27.96 | E10: Перегородки ГКЛ (ПГ-1, ПГ-2) за вычетом проёмов, м² | F10: 1 | G10: 0.05 | H10: =D10*F10*(1+G10) -> 29.358 | I10: 6 | J10: упак. | K10: =ROUNDUP(H10/I10,0) -> 5 | L10: упаковка ≈ 6 м² | N10: =IF(M10="","",K10*M10)
A11: 6 | B11: Лента демпферная 50 мм | C11: м | D11: =Объёмы!C24 -> 10.6 | E11: Длина перегородок ГКЛ, м | F11: 3 | G11: 0.1 | H11: =D11*F11*(1+G11) -> 34.98 | I11: 30 | J11: рулон | K11: =ROUNDUP(H11/I11,0) -> 2 | L11: под ПН и крайние ПС | N11: =IF(M11="","",K11*M11)
A12: 7 | B12: Дюбель-гвоздь 6×40 | C12: шт | D12: =Объёмы!C24 -> 10.6 | E12: Длина перегородок ГКЛ, м | F12: 6 | G12: 0.1 | H12: =D12*F12*(1+G12) -> 69.96 | I12: 100 | J12: упак. | K12: =ROUNDUP(H12/I12,0) -> 1 | L12: крепление ПН и ПС к перекрытиям и стенам | N12: =IF(M12="","",K12*M12)
A13: 8 | B13: Саморез ГКЛ 3,5×25 по металлу | C13: шт | D13: =Объёмы!C23 -> 27.96 | E13: Перегородки ГКЛ (ПГ-1, ПГ-2) за вычетом проёмов, м² | F13: 60 | G13: 0.1 | H13: =D13*F13*(1+G13) -> 1845.36 | I13: 1000 | J13: упак. | K13: =ROUNDUP(H13/I13,0) -> 2 | L13: ≈ 30 шт на м² листа | N13: =IF(M13="","",K13*M13)
A14: 9 | B14: Саморез «клоп» 3,5×9,5 (металл-металл) | C14: шт | D14: =Объёмы!C23 -> 27.96 | E14: Перегородки ГКЛ (ПГ-1, ПГ-2) за вычетом проёмов, м² | F14: 10 | G14: 0.1 | H14: =D14*F14*(1+G14) -> 307.56 | I14: 1000 | J14: упак. | K14: =ROUNDUP(H14/I14,0) -> 1 | N14: =IF(M14="","",K14*M14)
A15: 10 | B15: Серпянка 50 мм, 45 м | C15: м | D15: =Объёмы!C23 -> 27.96 | E15: Перегородки ГКЛ (ПГ-1, ПГ-2) за вычетом проёмов, м² | F15: 2.4 | G15: 0.1 | H15: =D15*F15*(1+G15) -> 73.8144 | I15: 45 | J15: рулон | K15: =ROUNDUP(H15/I15,0) -> 2 | L15: стыки листов и примыкания | N15: =IF(M15="","",K15*M15)
A16: 11 | B16: Шпаклёвка для швов ГКЛ (типа Фугенфюллер), 25 кг | C16: кг | D16: =Объёмы!C23 -> 27.96 | E16: Перегородки ГКЛ (ПГ-1, ПГ-2) за вычетом проёмов, м² | F16: 0.6 | G16: 0.1 | H16: =D16*F16*(1+G16) -> 18.4536 | I16: 25 | J16: мешок | K16: =ROUNDUP(H16/I16,0) -> 1 | N16: =IF(M16="","",K16*M16)
A17: 12 | B17: Закладные из фанеры 15 мм под ТВ, кондиционер, полки | C17: м² | D17: 1.5 | E17: по проекту | F17: 1 | G17: 0.1 | H17: =D17*F17*(1+G17) -> 1.65 | I17: 2.325625 | J17: лист | K17: =ROUNDUP(H17/I17,0) -> 1 | L17: лист 1525×1525 | N17: =IF(M17="","",K17*M17)
B18: 2. Перегородки из газоблока (ПГ-3, ПГ-4) | L18: газоблок D500 100 мм на клею
A19: 13 | B19: Газоблок D500 600×250×100 | C19: шт | D19: =Объёмы!C26 -> 11.43 | E19: Перегородки из газоблока (ПГ-3, ПГ-4), м² | F19: 6.67 | G19: 0.05 | H19: =D19*F19*(1+G19) -> 80.050005 | I19: 1 | J19: шт | K19: =ROUNDUP(H19/I19,0) -> 81 | L19: 6,67 шт на м² | N19: =IF(M19="","",K19*M19)
A20: 14 | B20: Клей для газоблока, 25 кг | C20: кг | D20: =Объёмы!C26 -> 11.43 | E20: Перегородки из газоблока (ПГ-3, ПГ-4), м² | F20: 2.5 | G20: 0.1 | H20: =D20*F20*(1+G20) -> 31.4325 | I20: 25 | J20: мешок | K20: =ROUNDUP(H20/I20,0) -> 2 | L20: ≈ 25 кг на м³ кладки | N20: =IF(M20="","",K20*M20)
A21: 15 | B21: Арматура Ø8 А500 для армирования кладки | C21: м | D21: =Объёмы!C27 -> 4.3 | E21: Длина перегородок из газоблока, м | F21: 8 | G21: 0.1 | H21: =D21*F21*(1+G21) -> 37.84 | I21: 6 | J21: прут 6 м | K21: =ROUNDUP(H21/I21,0) -> 7 | L21: каждый 3-й ряд, 2 прутка | N21: =IF(M21="","",K21*M21)
A22: 16 | B22: Пластины анкерные гибкие (связь со стенами) | C22: шт | D22: 4 | E22: по проекту | F22: 4 | G22: 0 | H22: =D22*F22*(1+G22) -> 16 | I22: 1 | J22: шт | K22: =ROUNDUP(H22/I22,0) -> 16 | L22: 4 примыкания × 4 ряда | N22: =IF(M22="","",K22*M22)
A23: 17 | B23: Уголок стальной 63×5 (перемычка над Д-3) | C23: м | D23: 2.2 | E23: по проекту | F23: 1 | G23: 0 | H23: =D23*F23*(1+G23) -> 2.2 | I23: 1 | J23: м | K23: =ROUNDUP(H23/I23,0) -> 3 | L23: 2 уголка по 1,1 м | N23: =IF(M23="","",K23*M23)
B24: 3. Стены: штукатурка и подготовка под покраску
A25: 18 | B25: Грунт глубокого проникновения, 10 л | C25: л | D25: =Объёмы!C65 -> 395.16 | E25: Грунтование: стены 2 раза, санузел, пол под стяжку и под покрытие, м² | F25: 0.15 | G25: 0.1 | H25: =D25*F25*(1+G25) -> 65.2014 | I25: 10 | J25: канистра | K25: =ROUNDUP(H25/I25,0) -> 7 | N25: =IF(M25="","",K25*M25)
A26: 19 | B26: Бетоноконтакт, 20 кг (по монолиту перед гипсовой штукатуркой) | C26: кг | D26: =Объёмы!C10 -> 79.25 | E26: Гипсовая штукатурка: наружные стены и газоблок в сухих помещениях, м² | F26: 0.3 | G26: 0.1 | H26: =D26*F26*(1+G26) -> 26.1525 | I26: 20 | J26: ведро | K26: =ROUNDUP(H26/I26,0) -> 2 | L26: если стены монолит | N26: =IF(M26="","",K26*M26)
A27: 20 | B27: Штукатурка гипсовая, 30 кг | C27: кг | D27: =Объёмы!C10 -> 79.25 | E27: Гипсовая штукатурка: наружные стены и газоблок в сухих помещениях, м² | F27: 12.75 | G27: 0.1 | H27: =D27*F27*(1+G27) -> 1111.4813 | I27: 30 | J27: мешок | K27: =ROUNDUP(H27/I27,0) -> 38 | L27: средний слой 15 мм, 8,5 кг/м² на 10 мм | N27: =IF(M27="","",K27*M27)
A28: 21 | B28: Штукатурка цементная для санузла, 25 кг | C28: кг | D28: =Объёмы!C11 -> 23.9 | E28: Цементная штукатурка в санузле, м² | F28: 17 | G28: 0.1 | H28: =D28*F28*(1+G28) -> 446.93 | I28: 25 | J28: мешок | K28: =ROUNDUP(H28/I28,0) -> 18 | L28: слой 10 мм под плитку | N28: =IF(M28="","",K28*M28)
A29: 22 | B29: Маяк штукатурный 6 мм, 3 м | C29: шт | D29: =Объёмы!C12 -> 38.2 | E29: Длина оштукатуриваемых стен для маяков, м | F29: 0.85 | G29: 0.1 | H29: =D29*F29*(1+G29) -> 35.717 | I29: 1 | J29: шт | K29: =ROUNDUP(H29/I29,0) -> 36 | L29: шаг 1,2 м | N29: =IF(M29="","",K29*M29)
A30: 23 | B30: Уголок перфорированный ПВХ с сеткой, 3 м | C30: м | D30: =Объёмы!C66 -> 29.8 | E30: Откосы дверей и окон, внешние углы под уголок, м | F30: 1 | G30: 0.1 | H30: =D30*F30*(1+G30) -> 32.78 | I30: 3 | J30: шт | K30: =ROUNDUP(H30/I30,0) -> 11 | L30: откосы и внешние углы | N30: =IF(M30="","",K30*M30)
A31: 24 | B31: Сетка стеклотканевая 5×5 на стыки разных материалов | C31: м² | D31: 10 | E31: по проекту | F31: 1 | G31: 0 | H31: =D31*F31*(1+G31) -> 10 | I31: 50 | J31: рулон | K31: =ROUNDUP(H31/I31,0) -> 1 | L31: стыки газоблока, ГКЛ и бетона | N31: =IF(M31="","",K31*M31)
A32: 25 | B32: Шпаклёвка финишная полимерная, 20 кг | C32: кг | D32: =Объёмы!C5 -> 131.12 | E32: Стены под покраску (комнаты и прихожая минус проёмы и фартук), м² | F32: 1.2 | G32: 0.1 | H32: =D32*F32*(1+G32) -> 173.0784 | I32: 20 | J32: мешок | K32: =ROUNDUP(H32/I32,0) -> 9 | L32: 2 тонких слоя | N32: =IF(M32="","",K32*M32)
A33: 26 | B33: Стеклохолст малярный (паутинка) 40 г/м² | C33: м² | D33: =Объёмы!C5 -> 131.12 | E33: Стены под покраску (комнаты и прихожая минус проёмы и фартук), м² | F33: 1.1 | G33: 0.05 | H33: =D33*F33*(1+G33) -> 151.4436 | I33: 50 | J33: рулон | K33: =ROUNDUP(H33/I33,0) -> 4 | L33: против трещин под покраской, рекомендуем | N33: =IF(M33="","",K33*M33)
A34: 27 | B34: Клей для стеклохолста готовый, 10 кг | C34: кг | D34: =Объёмы!C5 -> 131.12 | E34: Стены под покраску (комнаты и прихожая минус проёмы и фартук), м² | F34: 0.25 | G34: 0.1 | H34: =D34*F34*(1+G34) -> 36.058 | I34: 10 | J34: ведро | K34: =ROUNDUP(H34/I34,0) -> 4 | N34: =IF(M34="","",K34*M34)
A35: 28 | B35: Краска интерьерная матовая моющаяся, 9 л | C35: л | D35: =Объёмы!C5 -> 131.12 | E35: Стены под покраску (комнаты и прихожая минус проёмы и фартук), м² | F35: 0.24 | G35: 0.1 | H35: =D35*F35*(1+G35) -> 34.61568 | I35: 9 | J35: ведро | K35: =ROUNDUP(H35/I35,0) -> 4 | L35: 2 слоя по 0,12 л/м², колеровка грейж | N35: =IF(M35="","",K35*M35)
A36: 29 | B36: Герметик акриловый под покраску | C36: шт | D36: 6 | E36: по проекту | F36: 1 | G36: 0 | H36: =D36*F36*(1+G36) -> 6 | I36: 1 | J36: туба | K36: =ROUNDUP(H36/I36,0) -> 6 | L36: примыкания ГКЛ к стенам, откосы | N36: =IF(M36="","",K36*M36)
B37: 4. Полы: стяжка и покрытия
A38: 30 | B38: Подложка звукоизоляционная под стяжку 5 мм | C38: м² | D38: =Объёмы!C17 -> 54.51 | E38: Площадь пола всего, м² | F38: 1 | G38: 0.1 | H38: =D38*F38*(1+G38) -> 59.961 | I38: 10 | J38: рулон | K38: =ROUNDUP(H38/I38,0) -> 6 | N38: =IF(M38="","",K38*M38)
A39: 31 | B39: Плёнка полиэтиленовая 200 мкм | C39: м² | D39: =Объёмы!C17 -> 54.51 | E39: Площадь пола всего, м² | F39: 1.15 | G39: 0.05 | H39: =D39*F39*(1+G39) -> 65.820825 | I39: 100 | J39: рулон | K39: =ROUNDUP(H39/I39,0) -> 1 | L39: нахлёст на стены 100 мм | N39: =IF(M39="","",K39*M39)
A40: 32 | B40: Лента демпферная для стяжки 10×100 мм | C40: м | D40: =Объёмы!C19 -> 59.2 | E40: Периметр всех помещений, м | F40: 1 | G40: 0.05 | H40: =D40*F40*(1+G40) -> 62.16 | I40: 25 | J40: рулон | K40: =ROUNDUP(H40/I40,0) -> 3 | N40: =IF(M40="","",K40*M40)
A41: 33 | B41: Смесь ЦПС М150 (пескобетон), 40 кг | C41: кг | D41: =Объёмы!C18 -> 3153.86 | E41: Стяжка: площадь × толщина (60 / 54 / 48 мм), м²·мм | F41: 2 | G41: 0.05 | H41: =D41*F41*(1+G41) -> 6623.106 | I41: 40 | J41: мешок | K41: =ROUNDUP(H41/I41,0) -> 166 | L41: 20 кг на м² при слое 10 мм; слой 48–60 мм | N41: =IF(M41="","",K41*M41)
...

Sheet Объёмы
A1: Объёмы из проекта «Квартира 56 м²»
A2: Посчитаны по чертежам проекта. Синие числа можно менять — ведомость пересчитается.
A4: Код | B4: Что посчитано | C4: Значение
A5: S_paint | B5: Стены под покраску (комнаты и прихожая минус проёмы и фартук), м² | C5: 131.12
A6: S_tile_wall | B6: Стены санузла под плитку до потолка, м² | C6: 23.9
A7: S_tile_acc | B7: Акцентная стена санузла (вертикальная плитка), м² | C7: 6.34
A8: S_tile_main | B8: Остальные стены санузла, м² | C8: 17.56
A9: S_apron | B9: Кухонный фартук, м² | C9: 2.4
A10: S_plaster | B10: Гипсовая штукатурка: наружные стены и газоблок в сухих помещениях, м² | C10: 79.25
A11: S_plaster_c | B11: Цементная штукатурка в санузле, м² | C11: 23.9
A12: L_beacon | B12: Длина оштукатуриваемых стен для маяков, м | C12: 38.2
A13: S_lam | B13: Ламинат: спальня и кухня-гостиная, м² | C13: 39.67
A14: S_hall | B14: Керамогранит 600×600: прихожая, м² | C14: 10.21
A15: S_bathfl | B15: Керамогранит 300×600: пол санузла, м² | C15: 4.62
A16: S_heat | B16: Тёплый пол, м² | C16: 0.92
... A74: P_pipes_all | B74: Все трубы, м (для креплений) | C74: 14.04
